Workbook

Sheet All_India_Index_Upto_April23_RA
A1: Sector | B1: Year | C1: Month | D1: Cereals and products | E1: Meat and fish | F1: Egg | G1: Milk and products | H1: Oils and fats | I1: Fruits | J1: Vegetables | K1: Pulses and products | L1: Sugar and Confectionery | M1: Spices | N1: Non-alcoholic beverages | O1: Prepared meals, snacks, sweets etc. | P1: Food and beverages | Q1: Pan, tobacco and intoxicants | R1: Clothing | S1: Footwear | T1: Clothing and footwear | U1: Housing | V1: Fuel and light | W1: Household goods and services | X1: Health | Y1: Transport and communication | Z1: Recreation and amusement | AA1: Education | AB1: Personal care and effects | AC1: Miscellaneous | AD1: General index
A2: Rural | B2: 2013 | C2: January | D2: 107.5 | E2: 106.3 | F2: 108.1 | G2: 104.9 | H2: 106.1 | I2: 103.9 | J2: 101.9 | K2: 106.1 | L2: 106.8 | M2: 103.1 | N2: 104.8 | O2: 106.7 | P2: 105.5 | Q2: 105.1 | R2: 106.5 | S2: 105.8 | T2: 106.4 | U2: NA | V2: 105.5 | W2: 104.8 | X2: 104 | Y2: 103.3 | Z2: 103.4 | AA2: 103.8 | AB2: 104.7 | AC2: 104 | AD2: 105.1
A3: Urban | B3: 2013 | C3: January | D3: 110.5 | E3: 109.1 | F3: 113 | G3: 103.6 | H3: 103.4 | I3: 102.3 | J3: 102.9 | K3: 105.8 | L3: 105.1 | M3: 101.8 | N3: 105.1 | O3: 107.9 | P3: 105.9 | Q3: 105.2 | R3: 105.9 | S3: 105 | T3: 105.8 | U3: 100.3 | V3: 105.4 | W3: 104.8 | X3: 104.1 | Y3: 103.2 | Z3: 102.9 | AA3: 103.5 | AB3: 104.3 | AC3: 103.7 | AD3: 104
A4: Rural+Urban | B4: 2013 | C4: January | D4: 108.4 | E4: 107.3 | F4: 110 | G4: 104.4 | H4: 105.1 | I4: 103.2 | J4: 102.2 | K4: 106 | L4: 106.2 | M4: 102.7 | N4: 104.9 | O4: 107.3 | P4: 105.6 | Q4: 105.1 | R4: 106.3 | S4: 105.5 | T4: 106.2 | U4: 100.3 | V4: 105.5 | W4: 104.8 | X4: 104 | Y4: 103.2 | Z4: 103.1 | AA4: 103.6 | AB4: 104.5 | AC4: 103.9 | AD4: 104.6
A5: Rural | B5: 2013 | C5: February | D5: 109.2 | E5: 108.7 | F5: 110.2 | G5: 105.4 | H5: 106.7 | I5: 104 | J5: 102.4 | K5: 105.9 | L5: 105.7 | M5: 103.1 | N5: 105.1 | O5: 107.7 | P5: 106.3 | Q5: 105.6 | R5: 107.1 | S5: 106.3 | T5: 107 | U5: NA | V5: 106.2 | W5: 105.2 | X5: 104.4 | Y5: 103.9 | Z5: 104 | AA5: 104.1 | AB5: 104.6 | AC5: 104.4 | AD5: 105.8
A6: Urban | B6: 2013 | C6: February | D6: 112.9 | E6: 112.9 | F6: 116.9 | G6: 104 | H6: 103.5 | I6: 103.1 | J6: 104.9 | K6: 104.1 | L6: 103.8 | M6: 102.3 | N6: 106 | O6: 109 | P6: 107.2 | Q6: 106 | R6: 106.6 | S6: 105.5 | T6: 106.4 | U6: 100.4 | V6: 105.7 | W6: 105.2 | X6: 104.7 | Y6: 104.4 | Z6: 103.3 | AA6: 103.7 | AB6: 104.3 | AC6: 104.3 | AD6: 104.7
A7: Rural+Urban | B7: 2013 | C7: February | D7: 110.4 | E7: 110.2 | F7: 112.8 | G7: 104.9 | H7: 105.5 | I7: 103.6 | J7: 103.2 | K7: 105.3 | L7: 105.1 | M7: 102.8 | N7: 105.5 | O7: 108.3 | P7: 106.6 | Q7: 105.7 | R7: 106.9 | S7: 106 | T7: 106.8 | U7: 100.4 | V7: 106 | W7: 105.2 | X7: 104.5 | Y7: 104.2 | Z7: 103.6 | AA7: 103.9 | AB7: 104.5 | AC7: 104.4 | AD7: 105.3
A8: Rural | B8: 2013 | C8: March | D8: 110.2 | E8: 108.8 | F8: 109.9 | G8: 105.6 | H8: 106.2 | I8: 105.7 | J8: 101.4 | K8: 105.7 | L8: 105 | M8: 103.3 | N8: 105.6 | O8: 108.2 | P8: 106.6 | Q8: 106.5 | R8: 107.6 | S8: 106.8 | T8: 107.5 | U8: NA | V8: 106.1 | W8: 105.6 | X8: 104.7 | Y8: 104.6 | Z8: 104 | AA8: 104.3 | AB8: 104.3 | AC8: 104.6 | AD8: 106
A9: Urban | B9: 2013 | C9: March | D9: 113.9 | E9: 111.4 | F9: 113.2 | G9: 104.3 | H9: 102.7 | I9: 104.9 | J9: 103.8 | K9: 103.5 | L9: 102.6 | M9: 102.4 | N9: 107 | O9: 109.8 | P9: 107.3 | Q9: 106.8 | R9: 107.2 | S9: 106 | T9: 107 | U9: 100.4 | V9: 106 | W9: 105.7 | X9: 105.2 | Y9: 105.5 | Z9: 103.5 | AA9: 103.8 | AB9: 104.2 | AC9: 104.9 | AD9: 105
A10: Rural+Urban | B10: 2013 | C10: March | D10: 111.4 | E10: 109.7 | F10: 111.2 | G10: 105.1 | H10: 104.9 | I10: 105.3 | J10: 102.2 | K10: 105 | L10: 104.2 | M10: 103 | N10: 106.2 | O10: 108.9 | P10: 106.9 | Q10: 106.6 | R10: 107.4 | S10: 106.5 | T10: 107.3 | U10: 100.4 | V10: 106.1 | W10: 105.6 | X10: 104.9 | Y10: 105.1 | Z10: 103.7 | AA10: 104 | AB10: 104.3 | AC10: 104.7 | AD10: 105.5
A11: Rural | B11: 2013 | C11: April | D11: 110.2 | E11: 109.5 | F11: 106.9 | G11: 106.3 | H11: 105.7 | I11: 108.3 | J11: 103.4 | K11: 105.7 | L11: 104.2 | M11: 103.2 | N11: 106.5 | O11: 108.8 | P11: 107.1 | Q11: 107.1 | R11: 108.1 | S11: 107.4 | T11: 108 | U11: NA | V11: 106.5 | W11: 106.1 | X11: 105.1 | Y11: 104.4 | Z11: 104.5 | AA11: 104.8 | AB11: 102.7 | AC11: 104.6 | AD11: 106.4
A12: Urban | B12: 2013 | C12: April | D12: 114.6 | E12: 113.4 | F12: 106 | G12: 104.7 | H12: 102.1 | I12: 109.5 | J12: 109.7 | K12: 104.6 | L12: 102 | M12: 103.5 | N12: 108.2 | O12: 110.6 | P12: 108.8 | Q12: 108.5 | R12: 107.9 | S12: 106.4 | T12: 107.7 | U12: 100.5 | V12: 106.4 | W12: 106.5 | X12: 105.7 | Y12: 105 | Z12: 104 | AA12: 105.2 | AB12: 103.2 | AC12: 105.1 | AD12: 105.7
A13: Rural+Urban | B13: 2013 | C13: April | D13: 111.6 | E13: 110.9 | F13: 106.6 | G13: 105.7 | H13: 104.4 | I13: 108.9 | J13: 105.5 | K13: 105.3 | L13: 103.5 | M13: 103.3 | N13: 107.2 | O13: 109.6 | P13: 107.7 | Q13: 107.5 | R13: 108 | S13: 107 | T13: 107.9 | U13: 100.5 | V13: 106.5 | W13: 106.3 | X13: 105.3 | Y13: 104.7 | Z13: 104.2 | AA13: 105 | AB13: 102.9 | AC13: 104.8 | AD13: 106.1
... A259: Rural+Urban | B259: 2020 | C259: March | D259: 145.1 | E259: 167 | F259: 148.1 | G259: 151.5 | H259: 131.2 | I259: 142.5 | J259: 157.3 | K259: 141.1 | L259: 113.2 | M259: 153.2 | N259: 136.7 | O259: 159.6 | P259: 148.9 | Q259: 171.2 | R259: 151.2 | S259: 141.9 | T259: 149.8 | U259: 154.5 | V259: 148.9 | W259: 146.4 | X259: 152.3 | Y259: 129.9 | Z259: 143.7 | AA259: 156.1 | AB259: 145.2 | AC259: 143.8 | AD259: 148.6
A260: Rural | B260: 2020 | C260: April | D260: 147.2 | F260: 146.9 | G260: 155.6 | H260: 137.1 | I260: 147.3 | J260: 162.7 | K260: 150.2 | L260: 119.8 | M260: 158.7 | N260: 139.2 | P260: 150.1 | U260: NA | V260: 148.4 | X260: 154.3
A261: Urban | B261: 2020 | C261: April | D261: 151.8 | F261: 151.9 | G261: 155.5 | H261: 131.6 | I261: 152.9 | J261: 180 | K261: 150.8 | L261: 121.2 | M261: 154 | N261: 133.5 | P261: 153.5 | U261: 155.6 | V261: 137.1 | X261: 144.8
A262: Rural+Urban | B262: 2020 | C262: April | D262: 148.7 | F262: 148.8 | G262: 155.6 | H262: 135.1 | I262: 149.9 | J262: 168.6 | K262: 150.4 | L262: 120.3 | M262: 157.1 | N262: 136.8 | P262: 151.4 | U262: 155.6 | V262: 144.1 | X262: 150.7
A263: Rural | B263: 2020 | C263: May | U263: NA
A264: Urban | B264: 2020 | C264: May | U264: NA
A265: Rural+Urban | B265: 2020 | C265: May | U265: NA
A266: Rural | B266: 2020 | C266: June | D266: 148.2 | E266: 190.3 | F266: 149.4 | G266: 153.3 | H266: 138.2 | I266: 143.2 | J266: 148.9 | K266: 150.3 | L266: 113.2 | M266: 159.8 | N266: 142.1 | O266: 161.8 | P266: 152.3 | Q266: 182.4 | R266: 154.7 | S266: 150 | T266: 154.1 | U266: NA | V266: 144.9 | W266: 151.7 | X266: 158.2 | Y266: 141.4 | Z266: 153.2 | AA266: 161.8 | AB266: 151.2 | AC266: 151.7 | AD266: 152.7
A267: Urban | B267: 2020 | C267: June | D267: 152.7 | E267: 197 | F267: 154.6 | G267: 153.4 | H267: 132.9 | I267: 151.8 | J267: 171.2 | K267: 152 | L267: 116.3 | M267: 158.8 | N267: 135.6 | O267: 161.7 | P267: 157 | Q267: 186.7 | R267: 149.1 | S267: 136.6 | T267: 147.2 | U267: 154.7 | V267: 137.1 | W267: 140.4 | X267: 148.1 | Y267: 129.3 | Z267: 144.5 | AA267: 152.5 | AB267: 152.2 | AC267: 142 | AD267: 150.8
A268: Rural+Urban | B268: 2020 | C268: June | D268: 149.6 | E268: 192.7 | F268: 151.4 | G268: 153.3 | H268: 136.3 | I268: 147.2 | J268: 156.5 | K268: 150.9 | L268: 114.2 | M268: 159.5 | N268: 139.4 | O268: 161.8 | P268: 154 | Q268: 183.5 | R268: 152.5 | S268: 144.4 | T268: 151.4 | U268: 154.7 | V268: 141.9 | W268: 146.4 | X268: 154.4 | Y268: 135 | Z268: 148.3 | AA268: 156.4 | AB268: 151.6 | AC268: 147 | AD268: 151.8
A269: Rural | B269: 2020 | C269: July | D269: 148.2 | E269: 190.3 | F269: 149.4 | G269: 153.3 | H269: 138.2 | I269: 143.2 | J269: 148.9 | K269: 150.3 | L269: 113.2 | M269: 159.8 | N269: 142.1 | O269: 161.8 | P269: 152.3 | Q269: 182.4 | R269: 154.7 | S269: 150 | T269: 154.1 | U269: NA | V269: 144.9 | W269: 151.7 | X269: 158.2 | Y269: 141.4 | Z269: 153.2 | AA269: 161.8 | AB269: 151.2 | AC269: 151.7 | AD269: 152.7
A270: Urban | B270: 2020 | C270: July | D270: 152.7 | E270: 197 | F270: 154.6 | G270: 153.4 | H270: 132.9 | I270: 151.8 | J270: 171.2 | K270: 152 | L270: 116.3 | M270: 158.8 | N270: 135.6 | O270: 161.7 | P270: 157 | Q270: 186.7 | R270: 149.1 | S270: 136.6 | T270: 147.2 | U270: 154.7 | V270: 137.1 | W270: 140.4 | X270: 148.1 | Y270: 129.3 | Z270: 144.5 | AA270: 152.5 | AB270: 152.2 | AC270: 142 | AD270: 150.8
A271: Rural+Urban | B271: 2020 | C271: July | D271: 149.6 | E271: 192.7 | F271: 151.4 | G271: 153.3 | H271: 136.3 | I271: 147.2 | J271: 156.5 | K271: 150.9 | L271: 114.2 | M271: 159.5 | N271: 139.4 | O271: 161.8 | P271: 154 | Q271: 183.5 | R271: 152.5 | S271: 144.4 | T271: 151.4 | U271: 154.7 | V271: 141.9 | W271: 146.4 | X271: 154.4 | Y271: 135 | Z271: 148.3 | AA271: 156.4 | AB271: 151.6 | AC271: 147 | AD271: 151.8
A272: Rural | B272: 2020 | C272: August | D272: 147.6 | E272: 187.2 | F272: 148.4 | G272: 153.3 | H272: 139.8 | I272: 146.9 | J272: 171 | K272: 149.9 | L272: 114.2 | M272: 160 | N272: 143.5 | O272: 161.5 | P272: 155.3 | Q272: 180.9 | R272: 155.1 | S272: 149.3 | T272: 154.3 | U272: NA | V272: 145.8 | W272: 151.9 | X272: 158.8 | Y272: 143.6 | Z272: 152.2 | AA272: 162.7 | AB272: 153.6 | AC272: 153 | AD272: 154.7
A273: Urban | B273: 2020 | C273: August | D273: 151.6 | E273: 197.8 | F273: 154.5 | G273: 153.4 | H273: 133.4 | I273: 154.5 | J273: 191.9 | K273: 151.3 | L273: 116.8 | M273: 160 | N273: 136.5 | O273: 163.3 | P273: 159.9 | Q273: 187.2 | R273: 150 | S273: 135.2 | T273: 147.8 | U273: 155.5 | V273: 138.3 | W273: 144.5 | X273: 148.7 | Y273: 133.9 | Z273: 141.2 | AA273: 155.5 | AB273: 155.2 | AC273: 144.8 | AD273: 152.9
A274: Rural+Urban | B274: 2020 | C274: August | D274: 148.9 | E274: 190.9 | F274: 150.8 | G274: 153.3 | H274: 137.4 | I274: 150.4 | J274: 178.1 | K274: 150.4 | L274: 115.1 | M274: 160 | N274: 140.6 | O274: 162.3 | P274: 157 | Q274: 182.6 | R274: 153.1 | S274: 143.4 | T274: 151.7 | U274: 155.5 | V274: 143 | W274: 148.4 | X274: 155 | Y274: 138.5 | Z274: 146 | AA274: 158.5 | AB274: 154.3 | AC274: 149 | AD274: 153.9
A275: Rural | B275: 2020 | C275: September | D275: 146.9 | E275: 183.9 | F275: 149.5 | G275: 153.4 | H275: 140.4 | I275: 147 | J275: 178.8 | K275: 149.3 | L275: 115.1 | M275: 160 | N275: 145.4 | O275: 161.6 | P275: 156.1 | Q275: 182.9 | R275: 155.4 | S275: 149.9 | T275: 154.6 | U275: NA | V275: 146.4 | W275: 151.6 | X275: 159.1 | Y275: 144.6 | Z275: 152.8 | AA275: 161.1 | AB275: 157.4 | AC275: 153.7 | AD275: 155.4
A276: Urban | B276: 2020 | C276: September | D276: 151.5 | E276: 193.1 | F276: 157.3 | G276: 153.9 | H276: 134.4 | I276: 155.4 | J276: 202 | K276: 150.8 | L276: 118.9 | M276: 160.9 | N276: 137.7 | O276: 164.4 | P276: 161.3 | Q276: 188.7 | R276: 150.2 | S276: 136.3 | T276: 148.1 | U276: 156.3 | V276: 137.2 | W276: 145.4 | X276: 150 | Y276: 135.1 | Z276: 141.8 | AA276: 154.9 | AB276: 159.8 | AC276: 146 | AD276: 154
A277: Rural+Urban | B277: 2020 | C277: September | D277: 148.4 | E277: 187.1 | F277: 152.5 | G277: 153.6 | H277: 138.2 | I277: 150.9 | J277: 186.7 | K277: 149.8 | L277: 116.4 | M277: 160.3 | N277: 142.2 | O277: 162.9 | P277: 158 | Q277: 184.4 | R277: 153.4 | S277: 144.3 | T277: 152 | U277: 156.3 | V277: 142.9 | W277: 148.7 | X277: 155.6 | Y277: 139.6 | Z277: 146.6 | AA277: 157.5 | AB277: 158.4 | AC277: 150 | AD277: 154.7
... A373: Rural+Urban | B373: 2023 | C373: May | D373: 173.7 | E373: 214.3 | F373: 173.2 | G373: 179.5 | H373: 170 | I373: 172.2 | J373: 161 | K373: 175.6 | L373: 122.7 | M373: 218 | N373: 173.4 | O373: 194.2 | P373: 179.1 | Q373: 201 | R373: 187.3 | S373: 179.7 | T373: 186.2 | U373: 175.6 | V373: 182.8 | W373: 175.2 | X373: 185.7 | Y373: 164.8 | Z373: 171.2 | AA373: 177.1 | AB373: 185.2 | AC373: 175.7 | AD373: 179.1

Sheet Raw Data
A1: Sector | B1: Year | C1: Month | D1: Cereals and products | E1: Meat and fish | F1: Egg | G1: Milk and products | H1: Oils and fats | I1: Fruits | J1: Vegetables | K1: Pulses and products | L1: Sugar and Confectionery | M1: Spices | N1: Non-alcoholic beverages | O1: Prepared meals, snacks, sweets etc. | P1: Food and beverages | Q1: Pan, tobacco and intoxicants | R1: Clothing | S1: Footwear | T1: Clothing and footwear | U1: Housing | V1: Fuel and light | W1: Household goods and services | X1: Health | Y1: Transport and communication | Z1: Recreation and amusement | AA1: Education | AB1: Personal care and effects | AC1: Miscellaneous | AD1: General index
A2: Rural | B2: 2013 | C2: January | D2: 107.5 | E2: 106.3 | F2: 108.1 | G2: 104.9 | H2: 106.1 | I2: 103.9 | J2: 101.9 | K2: 106.1 | L2: 106.8 | M2: 103.1 | N2: 104.8 | O2: 106.7 | P2: 105.5 | Q2: 105.1 | R2: 106.5 | S2: 105.8 | T2: 106.4 | U2: NA | V2: 105.5 | W2: 104.8 | X2: 104 | Y2: 103.3 | Z2: 103.4 | AA2: 103.8 | AB2: 104.7 | AC2: 104 | AD2: 105.1
A3: Urban | B3: 2013 | C3: January | D3: 110.5 | E3: 109.1 | F3: 113 | G3: 103.6 | H3: 103.4 | I3: 102.3 | J3: 102.9 | K3: 105.8 | L3: 105.1 | M3: 101.8 | N3: 105.1 | O3: 107.9 | P3: 105.9 | Q3: 105.2 | R3: 105.9 | S3: 105 | T3: 105.8 | U3: 100.3 | V3: 105.4 | W3: 104.8 | X3: 104.1 | Y3: 103.2 | Z3: 102.9 | AA3: 103.5 | AB3: 104.3 | AC3: 103.7 | AD3: 104
A4: Rural+Urban | B4: 2013 | C4: January | D4: 108.4 | E4: 107.3 | F4: 110 | G4: 104.4 | H4: 105.1 | I4: 103.2 | J4: 102.2 | K4: 106 | L4: 106.2 | M4: 102.7 | N4: 104.9 | O4: 107.3 | P4: 105.6 | Q4: 105.1 | R4: 106.3 | S4: 105.5 | T4: 106.2 | U4: 100.3 | V4: 105.5 | W4: 104.8 | X4: 104 | Y4: 103.2 | Z4: 103.1 | AA4: 103.6 | AB4: 104.5 | AC4: 103.9 | AD4: 104.6
A5: Rural | B5: 2013 | C5: February | D5: 109.2 | E5: 108.7 | F5: 110.2 | G5: 105.4 | H5: 106.7 | I5: 104 | J5: 102.4 | K5: 105.9 | L5: 105.7 | M5: 103.1 | N5: 105.1 | O5: 107.7 | P5: 106.3 | Q5: 105.6 | R5: 107.1 | S5: 106.3 | T5: 107 | U5: NA | V5: 106.2 | W5: 105.2 | X5: 104.4 | Y5: 103.9 | Z5: 104 | AA5: 104.1 | AB5: 104.6 | AC5: 104.4 | AD5: 105.8
A6: Urban | B6: 2013 | C6: February | D6: 112.9 | E6: 112.9 | F6: 116.9 | G6: 104 | H6: 103.5 | I6: 103.1 | J6: 104.9 | K6: 104.1 | L6: 103.8 | M6: 102.3 | N6: 106 | O6: 109 | P6: 107.2 | Q6: 106 | R6: 106.6 | S6: 105.5 | T6: 106.4 | U6: 100.4 | V6: 105.7 | W6: 105.2 | X6: 104.7 | Y6: 104.4 | Z6: 103.3 | AA6: 103.7 | AB6: 104.3 | AC6: 104.3 | AD6: 104.7
A7: Rural+Urban | B7: 2013 | C7: February | D7: 110.4 | E7: 110.2 | F7: 112.8 | G7: 104.9 | H7: 105.5 | I7: 103.6 | J7: 103.2 | K7: 105.3 | L7: 105.1 | M7: 102.8 | N7: 105.5 | O7: 108.3 | P7: 106.6 | Q7: 105.7 | R7: 106.9 | S7: 106 | T7: 106.8 | U7: 100.4 | V7: 106 | W7: 105.2 | X7: 104.5 | Y7: 104.2 | Z7: 103.6 | AA7: 103.9 | AB7: 104.5 | AC7: 104.4 | AD7: 105.3
A8: Rural | B8: 2013 | C8: March | D8: 110.2 | E8: 108.8 | F8: 109.9 | G8: 105.6 | H8: 106.2 | I8: 105.7 | J8: 101.4 | K8: 105.7 | L8: 105 | M8: 103.3 | N8: 105.6 | O8: 108.2 | P8: 106.6 | Q8: 106.5 | R8: 107.6 | S8: 106.8 | T8: 107.5 | U8: NA | V8: 106.1 | W8: 105.6 | X8: 104.7 | Y8: 104.6 | Z8: 104 | AA8: 104.3 | AB8: 104.3 | AC8: 104.6 | AD8: 106
A9: Urban | B9: 2013 | C9: March | D9: 113.9 | E9: 111.4 | F9: 113.2 | G9: 104.3 | H9: 102.7 | I9: 104.9 | J9: 103.8 | K9: 103.5 | L9: 102.6 | M9: 102.4 | N9: 107 | O9: 109.8 | P9: 107.3 | Q9: 106.8 | R9: 107.2 | S9: 106 | T9: 107 | U9: 100.4 | V9: 106 | W9: 105.7 | X9: 105.2 | Y9: 105.5 | Z9: 103.5 | AA9: 103.8 | AB9: 104.2 | AC9: 104.9 | AD9: 105
A10: Rural+Urban | B10: 2013 | C10: March | D10: 111.4 | E10: 109.7 | F10: 111.2 | G10: 105.1 | H10: 104.9 | I10: 105.3 | J10: 102.2 | K10: 105 | L10: 104.2 | M10: 103 | N10: 106.2 | O10: 108.9 | P10: 106.9 | Q10: 106.6 | R10: 107.4 | S10: 106.5 | T10: 107.3 | U10: 100.4 | V10: 106.1 | W10: 105.6 | X10: 104.9 | Y10: 105.1 | Z10: 103.7 | AA10: 104 | AB10: 104.3 | AC10: 104.7 | AD10: 105.5
A11: Rural | B11: 2013 | C11: April | D11: 110.2 | E11: 109.5 | F11: 106.9 | G11: 106.3 | H11: 105.7 | I11: 108.3 | J11: 103.4 | K11: 105.7 | L11: 104.2 | M11: 103.2 | N11: 106.5 | O11: 108.8 | P11: 107.1 | Q11: 107.1 | R11: 108.1 | S11: 107.4 | T11: 108 | U11: NA | V11: 106.5 | W11: 106.1 | X11: 105.1 | Y11: 104.4 | Z11: 104.5 | AA11: 104.8 | AB11: 102.7 | AC11: 104.6 | AD11: 106.4
A12: Urban | B12: 2013 | C12: April | D12: 114.6 | E12: 113.4 | F12: 106 | G12: 104.7 | H12: 102.1 | I12: 109.5 | J12: 109.7 | K12: 104.6 | L12: 102 | M12: 103.5 | N12: 108.2 | O12: 110.6 | P12: 108.8 | Q12: 108.5 | R12: 107.9 | S12: 106.4 | T12: 107.7 | U12: 100.5 | V12: 106.4 | W12: 106.5 | X12: 105.7 | Y12: 105 | Z12: 104 | AA12: 105.2 | AB12: 103.2 | AC12: 105.1 | AD12: 105.7
A13: Rural+Urban | B13: 2013 | C13: April | D13: 111.6 | E13: 110.9 | F13: 106.6 | G13: 105.7 | H13: 104.4 | I13: 108.9 | J13: 105.5 | K13: 105.3 | L13: 103.5 | M13: 103.3 | N13: 107.2 | O13: 109.6 | P13: 107.7 | Q13: 107.5 | R13: 108 | S13: 107 | T13: 107.9 | U13: 100.5 | V13: 106.5 | W13: 106.3 | X13: 105.3 | Y13: 104.7 | Z13: 104.2 | AA13: 105 | AB13: 102.9 | AC13: 104.8 | AD13: 106.1
... A259: Rural+Urban | B259: 2020 | C259: March | D259: 145.1 | E259: 167 | F259: 148.1 | G259: 151.5 | H259: 131.2 | I259: 142.5 | J259: 157.3 | K259: 141.1 | L259: 113.2 | M259: 153.2 | N259: 136.7 | O259: 159.6 | P259: 148.9 | Q259: 171.2 | R259: 151.2 | S259: 141.9 | T259: 149.8 | U259: 154.5 | V259: 148.9 | W259: 146.4 | X259: 152.3 | Y259: 129.9 | Z259: 143.7 | AA259: 156.1 | AB259: 145.2 | AC259: 143.8 | AD259: 148.6
A260: Rural | B260: 2020 | C260: April | D260: 147.2 | E260: =SUM(E257,E266)/2 -> 178.55 | F260: 146.9 | G260: 155.6 | H260: 137.1 | I260: 147.3 | J260: 162.7 | K260: 150.2 | L260: 119.8 | M260: 158.7 | N260: 139.2 | O260: =SUM(O257,O266)/2 -> 160.9 | P260: 150.1 | Q260: =SUM(Q257,Q266)/2 -> 176.45 | R260: =SUM(R257,R266)/2 -> 154.05 | S260: =SUM(S257,S266)/2 -> 148.8 | T260: =SUM(T257,T266)/2 -> 153.3 | U260: NA | V260: 148.4 | W260: =SUM(W257,W266)/2 -> 151.6 | X260: 154.3 | Y260: =SUM(Y257,Y266)/2 -> 138.6 | Z260: =SUM(Z257,Z266)/2 -> 152.2 | AA260: =SUM(AA257,AA266)/2 -> 161.5 | AB260: =SUM(AB257,AB266)/2 -> 148.15 | AC260: =SUM(AC257,AC266)/2 -> 150.15 | AD260: =SUM(AD257,AD266)/2 -> 151.25
A261: Urban | B261: 2020 | C261: April | D261: 151.8 | E261: =SUM(E258,E267)/2 -> 182.25 | F261: 151.9 | G261: 155.5 | H261: 131.6 | I261: 152.9 | J261: 180 | K261: 150.8 | L261: 121.2 | M261: 154 | N261: 133.5 | O261: =SUM(O258,O267)/2 -> 160.4 | P261: 153.5 | Q261: =SUM(Q258,Q267)/2 -> 180 | R261: =SUM(R258,R267)/2 -> 148.4 | S261: =SUM(S258,S267)/2 -> 135.2 | T261: =SUM(T258,T267)/2 -> 146.4 | U261: 155.6 | V261: 137.1 | W261: =SUM(W258,W267)/2 -> 140.6 | X261: 144.8 | Y261: =SUM(Y258,Y267)/2 -> 126.95 | Z261: =SUM(Z258,Z267)/2 -> 141.2 | AA261: =SUM(AA258,AA267)/2 -> 152.5 | AB261: =SUM(AB258,AB267)/2 -> 148.75 | AC261: =SUM(AC258,AC267)/2 -> 140.35 | AD261: =SUM(AD258,AD267)/2 -> 149.05
A262: Rural+Urban | B262: 2020 | C262: April | D262: 148.7 | E262: =SUM(E259,E268)/2 -> 179.85 | F262: 148.8 | G262: 155.6 | H262: 135.1 | I262: 149.9 | J262: 168.6 | K262: 150.4 | L262: 120.3 | M262: 157.1 | N262: 136.8 | O262: =SUM(O259,O268)/2 -> 160.7 | P262: 151.4 | Q262: =SUM(Q259,Q268)/2 -> 177.35 | R262: =SUM(R259,R268)/2 -> 151.85 | S262: =SUM(S259,S268)/2 -> 143.15 | T262: =SUM(T259,T268)/2 -> 150.6 | U262: 155.6 | V262: 144.1 | W262: =SUM(W259,W268)/2 -> 146.4 | X262: 150.7 | Y262: =SUM(Y259,Y268)/2 -> 132.45 | Z262: =SUM(Z259,Z268)/2 -> 146 | AA262: =SUM(AA259,AA268)/2 -> 156.25 | AB262: =SUM(AB259,AB268)/2 -> 148.4 | AC262: =SUM(AC259,AC268)/2 -> 145.4 | AD262: =SUM(AD259,AD268)/2 -> 150.2
A263: Rural | B263: 2020 | C263: May | D263: =SUM(D260,D266)/2 -> 147.7 | E263: =SUM(E260,E266)/2 -> 184.425 | F263: =SUM(F260,F266)/2 -> 148.15 | G263: =SUM(G260,G266)/2 -> 154.45 | H263: =SUM(H260,H266)/2 -> 137.65 | I263: =SUM(I260,I266)/2 -> 145.25 | J263: =SUM(J260,J266)/2 -> 155.8 | K263: =SUM(K260,K266)/2 -> 150.25 | ... T263: =SUM(T260,T266)/2 -> 153.7 | U263: NA | V263: =SUM(V260,V266)/2 -> 146.65 | W263: =SUM(W260,W266)/2 -> 151.65 | X263: =SUM(X260,X266)/2 -> 156.25 | Y263: =SUM(Y260,Y266)/2 -> 140 | Z263: =SUM(Z260,Z266)/2 -> 152.7 | AA263: =SUM(AA260,AA266)/2 -> 161.65 | AB263: =SUM(AB260,AB266)/2 -> 149.675 | AC263: =SUM(AC260,AC266)/2 -> 150.925 | AD263: =SUM(AD260,AD266)/2 -> 151.975
A264: Urban | B264: 2020 | C264: May | D264: =SUM(D261,D267)/2 -> 152.25 | E264: =SUM(E261,E267)/2 -> 189.625 | F264: =SUM(F261,F267)/2 -> 153.25 | G264: =SUM(G261,G267)/2 -> 154.45 | H264: =SUM(H261,H267)/2 -> 132.25 | I264: =SUM(I261,I267)/2 -> 152.35 | J264: =SUM(J261,J267)/2 -> 175.6 | K264: =SUM(K263,K265)/2 -> 150.45 | L264: =SUM(L261,L267)/2 -> 118.75 | M264: =SUM(M261,M267)/2 -> 156.4 | N264: =SUM(N261,N267)/2 -> 134.55 | O264: =SUM(O261,O267)/2 -> 161.05 | P264: =SUM(P261,P267)/2 -> 155.25 | Q264: =SUM(Q261,Q267)/2 -> 183.35 | R264: =SUM(R261,R267)/2 -> 148.75 | S264: =SUM(S261,S267)/2 -> 135.9 | T264: =SUM(T261,T267)/2 -> 146.8 | U264: NA | V264: =SUM(V261,V267)/2 -> 137.1 | W264: =SUM(,W261,W267)/2 -> 140.5 | X264: =SUM(X261,X267)/2 -> 146.45 | Y264: =SUM(Y261,Y267)/2 -> 128.125 | Z264: =SUM(Z261,Z267)/2 -> 142.85 | AA264: =SUM(AA261,AA267)/2 -> 152.5 | AB264: =SUM(AB261,AB267)/2 -> 150.475 | AC264: =SUM(AC261,AC267)/2 -> 141.175 | AD264: =SUM(AD261,AD267)/2 -> 149.925
A265: Rural+Urban | B265: 2020 | C265: May | D265: =SUM(D262,D268)/2 -> 149.15 | E265: =SUM(E262,E268)/2 -> 186.275 | F265: =SUM(F262,F268)/2 -> 150.1 | G265: =SUM(G262,G268)/2 -> 154.45 | H265: =SUM(H262,H268)/2 -> 135.7 | I265: =SUM(I262,I268)/2 -> 148.55 | J265: =SUM(J262,J268)/2 -> 162.55 | K265: =SUM(K262,K268)/2 -> 150.65 | ... T265: =SUM(T262,T268)/2 -> 151 | U265: NA | V265: =SUM(V262,V268)/2 -> 143 | W265: =SUM(W262,W268)/2 -> 146.4 | X265: =SUM(X262,X268)/2 -> 152.55 | Y265: =SUM(Y262,Y268)/2 -> 133.725 | Z265: =SUM(Z262,Z268)/2 -> 147.15 | AA265: =SUM(AA262,AA268)/2 -> 156.325 | AB265: =SUM(AB262,AB268)/2 -> 150 | AC265: =SUM(AC262,AC268)/2 -> 146.2 | AD265: =SUM(AD262,AD268)/2 -> 151
A266: Rural | B266: 2020 | C266: June | D266: 148.2 | E266: 190.3 | F266: 149.4 | G266: 153.3 | H266: 138.2 | I266: 143.2 | J266: 148.9 | K266: 150.3 | L266: 113.2 | M266: 159.8 | N266: 142.1 | O266: 161.8 | P266: 152.3 | Q266: 182.4 | R266: 154.7 | S266: 150 | T266: 154.1 | U266: NA | V266: 144.9 | W266: 151.7 | X266: 158.2 | Y266: 141.4 | Z266: 153.2 | AA266: 161.8 | AB266: 151.2 | AC266: 151.7 | AD266: 152.7
A267: Urban | B267: 2020 | C267: June | D267: 152.7 | E267: 197 | F267: 154.6 | G267: 153.4 | H267: 132.9 | I267: 151.8 | J267: 171.2 | K267: 152 | L267: 116.3 | M267: 158.8 | N267: 135.6 | O267: 161.7 | P267: 157 | Q267: 186.7 | R267: 149.1 | S267: 136.6 | T267: 147.2 | U267: 154.7 | V267: 137.1 | W267: 140.4 | X267: 148.1 | Y267: 129.3 | Z267: 144.5 | AA267: 152.5 | AB267: 152.2 | AC267: 142 | AD267: 150.8
A268: Rural+Urban | B268: 2020 | C268: June | D268: 149.6 | E268: 192.7 | F268: 151.4 | G268: 153.3 | H268: 136.3 | I268: 147.2 | J268: 156.5 | K268: 150.9 | L268: 114.2 | M268: 159.5 | N268: 139.4 | O268: 161.8 | P268: 154 | Q268: 183.5 | R268: 152.5 | S268: 144.4 | T268: 151.4 | U268: 154.7 | V268: 141.9 | W268: 146.4 | X268: 154.4 | Y268: 135 | Z268: 148.3 | AA268: 156.4 | AB268: 151.6 | AC268: 147 | AD268: 151.8
A269: Rural | B269: 2020 | C269: July | D269: 148.2 | E269: 190.3 | F269: 149.4 | G269: 153.3 | H269: 138.2 | I269: 143.2 | J269: 148.9 | K269: 150.3 | L269: 113.2 | M269: 159.8 | N269: 142.1 | O269: 161.8 | P269: 152.3 | Q269: 182.4 | R269: 154.7 | S269: 150 | T269: 154.1 | U269: NA | V269: 144.9 | W269: 151.7 | X269: 158.2 | Y269: 141.4 | Z269: 153.2 | AA269: 161.8 | AB269: 151.2 | AC269: 151.7 | AD269: 152.7
A270: Urban | B270: 2020 | C270: July | D270: 152.7 | E270: 197 | F270: 154.6 | G270: 153.4 | H270: 132.9 | I270: 151.8 | J270: 171.2 | K270: 152 | L270: 116.3 | M270: 158.8 | N270: 135.6 | O270: 161.7 | P270: 157 | Q270: 186.7 | R270: 149.1 | S270: 136.6 | T270: 147.2 | U270: 154.7 | V270: 137.1 | W270: 140.4 | X270: 148.1 | Y270: 129.3 | Z270: 144.5 | AA270: 152.5 | AB270: 152.2 | AC270: 142 | AD270: 150.8
A271: Rural+Urban | B271: 2020 | C271: July | D271: 149.6 | E271: 192.7 | F271: 151.4 | G271: 153.3 | H271: 136.3 | I271: 147.2 | J271: 156.5 | K271: 150.9 | L271: 114.2 | M271: 159.5 | N271: 139.4 | O271: 161.8 | P271: 154 | Q271: 183.5 | R271: 152.5 | S271: 144.4 | T271: 151.4 | U271: 154.7 | V271: 141.9 | W271: 146.4 | X271: 154.4 | Y271: 135 | Z271: 148.3 | AA271: 156.4 | AB271: 151.6 | AC271: 147 | AD271: 151.8
A272: Rural | B272: 2020 | C272: August | D272: 147.6 | E272: 187.2 | F272: 148.4 | G272: 153.3 | H272: 139.8 | I272: 146.9 | J272: 171 | K272: 149.9 | L272: 114.2 | M272: 160 | N272: 143.5 | O272: 161.5 | P272: 155.3 | Q272: 180.9 | R272: 155.1 | S272: 149.3 | T272: 154.3 | U272: NA | V272: 145.8 | W272: 151.9 | X272: 158.8 | Y272: 143.6 | Z272: 152.2 | AA272: 162.7 | AB272: 153.6 | AC272: 153 | AD272: 154.7
A273: Urban | B273: 2020 | C273: August | D273: 151.6 | E273: 197.8 | F273: 154.5 | G273: 153.4 | H273: 133.4 | I273: 154.5 | J273: 191.9 | K273: 151.3 | L273: 116.8 | M273: 160 | N273: 136.5 | O273: 163.3 | P273: 159.9 | Q273: 187.2 | R273: 150 | S273: 135.2 | T273: 147.8 | U273: 155.5 | V273: 138.3 | W273: 144.5 | X273: 148.7 | Y273: 133.9 | Z273: 141.2 | AA273: 155.5 | AB273: 155.2 | AC273: 144.8 | AD273: 152.9
A274: Rural+Urban | B274: 2020 | C274: August | D274: 148.9 | E274: 190.9 | F274: 150.8 | G274: 153.3 | H274: 137.4 | I274: 150.4 | J274: 178.1 | K274: 150.4 | L274: 115.1 | M274: 160 | N274: 140.6 | O274: 162.3 | P274: 157 | Q274: 182.6 | R274: 153.1 | S274: 143.4 | T274: 151.7 | U274: 155.5 | V274: 143 | W274: 148.4 | X274: 155 | Y274: 138.5 | Z274: 146 | AA274: 158.5 | AB274: 154.3 | AC274: 149 | AD274: 153.9
A275: Rural | B275: 2020 | C275: September | D275: 146.9 | E275: 183.9 | F275: 149.5 | G275: 153.4 | H275: 140.4 | I275: 147 | J275: 178.8 | K275: 149.3 | L275: 115.1 | M275: 160 | N275: 145.4 | O275: 161.6 | P275: 156.1 | Q275: 182.9 | R275: 155.4 | S275: 149.9 | T275: 154.6 | U275: NA | V275: 146.4 | W275: 151.6 | X275: 159.1 | Y275: 144.6 | Z275: 152.8 | AA275: 161.1 | AB275: 157.4 | AC275: 153.7 | AD275: 155.4
A276: Urban | B276: 2020 | C276: September | D276: 151.5 | E276: 193.1 | F276: 157.3 | G276: 153.9 | H276: 134.4 | I276: 155.4 | J276: 202 | K276: 150.8 | L276: 118.9 | M276: 160.9 | N276: 137.7 | O276: 164.4 | P276: 161.3 | Q276: 188.7 | R276: 150.2 | S276: 136.3 | T276: 148.1 | U276: 156.3 | V276: 137.2 | W276: 145.4 | X276: 150 | Y276: 135.1 | Z276: 141.8 | AA276: 154.9 | AB276: 159.8 | AC276: 146 | AD276: 154
A277: Rural+Urban | B277: 2020 | C277: September | D277: 148.4 | E277: 187.1 | F277: 152.5 | G277: 153.6 | H277: 138.2 | I277: 150.9 | J277: 186.7 | K277: 149.8 | L277: 116.4 | M277: 160.3 | N277: 142.2 | O277: 162.9 | P277: 158 | Q277: 184.4 | R277: 153.4 | S277: 144.3 | T277: 152 | U277: 156.3 | V277: 142.9 | W277: 148.7 | X277: 155.6 | Y277: 139.6 | Z277: 146.6 | AA277: 157.5 | AB277: 158.4 | AC277: 150 | AD277: 154.7
... A373: Rural+Urban | B373: 2023 | C373: May | D373: 173.7 | E373: 214.3 | F373: 173.2 | G373: 179.5 | H373: 170 | I373: 172.2 | J373: 161 | K373: 175.6 | L373: 122.7 | M373: 218 | N373: 173.4 | O373: 194.2 | P373: 179.1 | Q373: 201 | R373: 187.3 | S373: 179.7 | T373: 186.2 | U373: 175.6 | V373: 182.8 | W373: 175.2 | X373: 185.7 | Y373: 164.8 | Z373: 171.2 | AA373: 177.1 | AB373: 185.2 | AC373: 175.7 | AD373: 179.1

Sheet Notes
A1: Password for main data sheet - Bhagya
A3: Notes: The corrections that were made in the data, for solving the problem statement.
A4: Column Name | B4: Remarks | C4: Corrections done
A5: Sector | B5: Represents various categories of goods and services for Rural, Urban, Rural+Urban. | C5: No corrections was done in this column.
A6: Year | B6: The year the CPI data was recorded | C6: No corrections was made in this column.
A7: Month | B7: The month corresponding to the CPI data. | C7: No corrections was done in this column.
A8: Cereals and products | B8: Price index for cereals and related products. | C8: Missing values was handled by moving averages for May 2020
A9: Meat and fish | B9: Price index for meat and fish products. | C9: Missing values was handled by moving averages for April, May 2020.
A10: Egg | B10: Price index for eggs. | C10: Missing values was handled by moving averages for May 2020
A11: Milk and products | B11: Price index for milk and dairy products. | C11: Missing values was handled by moving averages.
A12: Oils and fats | B12: Price index for oils and fats. | C12: Missing values was handled by moving averages.
A13: Fruits | B13: Price index for fruits. | C13: Missing values was handled by moving averages.
A14: Vegetables | B14: Price index for vegetables. | C14: Missing values was handled by moving averages.
A15: Pulses and products | B15: Price index for pulses (lentils, bean) and products. | C15: Missing values was handled by moving averages.
... A34: General index | B34: The overall inflation index that combines all categories | C34: Missing values was handled by moving averages for April, May 2020.

Sheet PS1
A1: 45047
A2: The following is done for problem statement 1.
A3: 1.Based on the latest month’s data, identify the contribution of different broader categories (food, energy, transportation, education, etc.) towards the CPI basket. Broader categories (buckets) can be created by combining similar categories into one bucket; Ex.: Meals, Beverages, Cereals, can be clubbed to create “Food” category, etc.
A4: Which broader category has the highest contribution towards CPI calculation
A5: Contribution is calculated by evaluating the underlying index values for broader category and should add to 100% when contribution from different broader categories are added .
A6: Sector | B6: Category | C6: Rural | D6: Urban | E6: Rural+Urban | I6: Rural | J6: Rural% | K6: Urban | L6: Urban% | M6: Rural+Urban | N6: Rural+Urban%
A7: Cereals and products | B7: Food | C7: 173.2 | D7: 174.7 | E7: 173.7 | H7: Food | I7: =SUMIF($B$7:$B$32,H7,$C$7:$C$32) -> 2290.7 | J7: =I7/$I$13 -> 0.50918023 | K7: =SUMIF($B$7:$B$32,H7,$D$7:$D$32) -> 2335.1 | L7: =K7/$K$13 -> 0.52294359 | M7: =SUMIF($B$7:$B$32,H7,$E$7:$E$32) -> 2306.9 | N7: =M7/$M$13 -> 0.515071
A8: Meat and fish | B8: Food | C8: 211.5 | D8: 219.4 | E8: 214.3 | H8: Misc | I8: =SUMIF($B$7:$B$32,H8,$C$7:$C$32) -> 1088.1 | J8: =I8/$I$13 -> 0.2418645 | K8: =SUMIF($B$7:$B$32,H8,$D$7:$D$32) -> 1065.8 | L8: =K8/$K$13 -> 0.23868497 | M8: =SUMIF($B$7:$B$32,H8,$E$7:$E$32) -> 1075 | N8: =M8/$M$13 -> 0.24001965
A9: Egg | B9: Food | C9: 171 | D9: 176.7 | E9: 173.2 | H9: Clothing | I9: =SUMIF($B$7:$B$32,H9,$C$7:$C$32) -> 569.9 | J9: =I9/$I$13 -> 0.12667823 | K9: =SUMIF($B$7:$B$32,H9,$D$7:$D$32) -> 528.7 | L9: =K9/$K$13 -> 0.1184019 | M9: =SUMIF($B$7:$B$32,H9,$E$7:$E$32) -> 553.2 | N9: =M9/$M$13 -> 0.12351523
A10: Milk and products | B10: Food | C10: 179.6 | D10: 179.4 | E10: 179.5 | H10: Housing | I10: =SUMIF($B$7:$B$32,H10,$C$7:$C$32) -> 179.8 | J10: =I10/$I$13 -> 0.039966213 | K10: =SUMIF($B$7:$B$32,H10,$D$7:$D$32) -> 170.1 | L10: =K10/$K$13 -> 0.038093745 | M10: =SUMIF($B$7:$B$32,H10,$E$7:$E$32) -> 175.2 | N10: =M10/$M$13 -> 0.039117621
A11: Oils and fats | B11: Food | C11: 173.3 | D11: 164.4 | E11: 170 | H11: Energy | I11: =SUMIF($B$7:$B$32,H11,$C$7:$C$32) -> 182.5 | J11: =I11/$I$13 -> 0.040566373 | K11: =SUMIF($B$7:$B$32,H11,$D$7:$D$32) -> 183.4 | L11: =K11/$K$13 -> 0.041072268 | M11: =SUMIF($B$7:$B$32,H11,$E$7:$E$32) -> 182.8 | N11: =M11/$M$13 -> 0.040814504
A12: Fruits | B12: Food | C12: 169 | D12: 175.8 | E12: 172.2 | H12: Health | I12: =SUMIF($B$7:$B$32,H12,$C$7:$C$32) -> 187.8 | J12: =I12/$I$13 -> 0.041744465 | K12: =SUMIF($B$7:$B$32,H12,$D$7:$D$32) -> 182.2 | L12: =K12/$K$13 -> 0.040803529 | M12: =SUMIF($B$7:$B$32,H12,$E$7:$E$32) -> 185.7 | N12: =M12/$M$13 -> 0.041461999
A13: Vegetables | B13: Food | C13: 148.7 | D13: 185 | E13: 161 | I13: =SUM(I7:I12) -> 4498.8 | K13: =SUM(K7:K12) -> 4465.3 | M13: =SUM(M7:M12) -> 4478.8
A14: Pulses and products | B14: Food | C14: 174.9 | D14: 176.9 | E14: 175.6
A15: Sugar and Confectionery | B15: Food | C15: 121.9 | D15: 124.2 | E15: 122.7
A16: Spices | B16: Food | C16: 221 | D16: 211.9 | E16: 218
A17: Non-alcoholic beverages | B17: Food | C17: 178.7 | D17: 165.9 | E17: 173.4
A18: Prepared meals, snacks, sweets etc. | B18: Food | C18: 191.1 | D18: 197.7 | E18: 194.2
A19: Food and beverages | B19: Food | C19: 176.8 | D19: 183.1 | E19: 179.1
A20: Pan, tobacco and intoxicants | B20: Misc | C20: 199.9 | D20: 204.2 | E20: 201
A21: Clothing | B21: Clothing | C21: 191.2 | D21: 181.3 | E21: 187.3
A22: Footwear | B22: Clothing | C22: 187.9 | D22: 168.1 | E22: 179.7
A23: Clothing and footwear | B23: Clothing | C23: 190.8 | D23: 179.3 | E23: 186.2
A24: Housing | B24: Housing | C24: - | D24: 175.6 | E24: 175.6
A25: Fuel and light | B25: Energy | C25: 182.5 | D25: 183.4 | E25: 182.8
A26: Household goods and services | B26: Housing | C26: 179.8 | D26: 170.1 | E26: 175.2
A27: Health | B27: Health | C27: 187.8 | D27: 182.2 | E27: 185.7
A28: Transport and communication | B28: Misc | C28: 169.7 | D28: 160.4 | E28: 164.8
A29: Recreation and amusement | B29: Misc | C29: 173.8 | D29: 169.2 | E29: 171.2
A30: Education | B30: Misc | C30: 180.3 | D30: 174.8 | E30: 177.1
A31: Personal care and effects | B31: Misc | C31: 184.9 | D31: 185.6 | E31: 185.2
A32: Miscellaneous | B32: Misc | C32: 179.5 | D32: 171.6 | E32: 175.7

Sheet PS2
A1: 2. A trend of Y-o-Y increase in CPI (rural + urban) inflation starting 2017 for the entire basket of products combined.
A2: Qa. Create a graph depicting the growth rate Y-o-Y and identify the year with highest inflation rate
A3: (Rural+Urban) | G3: Rural | M3: Urban
A4: Years | B4: Jan | C4: Dec | D4: YoY% Change | G4: Years | H4: Jan | I4: Dec | J4: YoY%Change | M4: Years | N4: Jan | O4: Dec | P4: YoY%Change
A5: 2017 | B5: 130.3 | C5: 137.2 | D5: =(C5-B5)/B5 -> 0.05295472 | G5: 2017 | H5: 132.4 | I5: 139.8 | J5: =(I5-H5)/H5 -> 0.055891239 | M5: 2017 | N5: 127.8 | O5: 134.1 | P5: =(O5-N5)/N5 -> 0.049295775
A6: =A5+1 -> 2018 | B6: 136.9 | C6: 140.1 | D6: =(C6-B6)/B6 -> 0.023374726 | G6: =G5+1 -> 2018 | H6: 139.3 | I6: 141.9 | J6: =(I6-H6)/H6 -> 0.018664752 | M6: =M5+1 -> 2018 | N6: 134.1 | O6: 138 | P6: =(O6-N6)/N6 -> 0.029082774
A7: =A6+1 -> 2019 | B7: 139.6 | C7: 150.4 | D7: =(C7-B7)/B7 -> 0.077363897 | G7: =G6+1 -> 2019 | H7: 141 | I7: 152.3 | J7: =(I7-H7)/H7 -> 0.080141844 | M7: =M6+1 -> 2019 | N7: 138 | O7: 148.3 | P7: =(O7-N7)/N7 -> 0.074637681
A8: =A7+1 -> 2020 | B8: 150.2 | C8: 158.9 | D8: =(C8-B8)/B8 -> 0.05792277 | G8: =G7+1 -> 2020 | H8: 151.9 | I8: 160.7 | J8: =(I8-H8)/H8 -> 0.057932851 | M8: =M7+1 -> 2020 | N8: 148.2 | O8: 156.9 | P8: =(O8-N8)/N8 -> 0.058704453
A9: =A8+1 -> 2021 | B9: 157.3 | C9: 166.2 | D9: =(C9-B9)/B9 -> 0.056579784 | G9: =G8+1 -> 2021 | H9: 158.5 | I9: 167 | J9: =(I9-H9)/H9 -> 0.05362776 | M9: =M8+1 -> 2021 | N9: 156 | O9: 165.2 | P9: =(O9-N9)/N9 -> 0.058974359
A10: =A9+1 -> 2022 | B10: 165.7 | C10: 175.7 | D10: =(C10-B10)/B10 -> 0.06035003 | G10: =G9+1 -> 2022 | H10: 166.4 | I10: 177.1 | J10: =(I10-H10)/H10 -> 0.064302885 | M10: =M9+1 -> 2022 | N10: 165 | O10: 174.1 | P10: =(O10-N10)/N10 -> 0.055151515
A11: =A10+1 -> 2023 | B11: 176.5 | D11: We only have data till may 2023 | G11: =G10+1 -> 2023 | H11: 177.8 | J11: We only have data till may 2023 | M11: =M10+1 -> 2023 | N11: 174.9 | P11: We only have data till May 2023
A13: Highest Inflation in year 2019
A17: Qb. Highlight the reason why the year has the highest inflation (based on research)
A18: Rural+Urban
A19: Category Wise
A20: Food | F20: Miscellaneous | K20: Clothing | Q20: Housing | V20: Energy | AA20: Health
A21: Years | B21: Jan | C21: Dec | D21: YoY%Change | F21: Years | G21: Jan | H21: Dec | I21: YoY%Change | K21: Years | L21: Jan | M21: Dec | N21: YoY%Change | Q21: Years | R21: Jan | S21: Dec | T21: YoY%Change | V21: Years | W21: Jan | X21: Dec | Y21: YoY%Change | AA21: Years | AB21: Jan | AC21: Dec | AD21: YoY%Change
A22: 2017 | B22: ='Raw Data'!D148+'Raw Data'!E148+'Raw Data'!F148+'Raw Data'!G148++'Raw Data'!H148+'Raw Data'!I148+'Raw Data'!J148+'Raw Data'!K148+'Raw Data'!L148+'Raw Data'!M148+'Raw Data'!N148+'Raw Data'!O148+'Raw Data'!P148 -> 1727.3 | C22: =SUM('Raw Data'!D181:P181) -> 1795 | D22: =(C22-B22)/B22 -> 0.039194118 | F22: 2017 | G22: ='Raw Data'!Q148+'Raw Data'!Y148+'Raw Data'!Z148+'Raw Data'!AA148+'Raw Data'!AB148+'Raw Data'!AC148 -> 764.4 | H22: ='Raw Data'!Q181+'Raw Data'!Y181+'Raw Data'!Z181+'Raw Data'!AA181+'Raw Data'!AB181+'Raw Data'!AC181 -> 795.3 | I22: =(H22-G22)/G22 -> 0.040423862 | K22: 2017 | L22: =SUM('Raw Data'!R148:T148) -> 402.4 | M22: =SUM('Raw Data'!R181:T181) -> 420.2 | N22: =(M22-L22)/L22 -> 0.044234592 | Q22: 2017 | R22: ='Raw Data'!U148+'Raw Data'!W148 -> 259 | S22: ='Raw Data'!U181+'Raw Data'!W181 -> 273.8 | T22: =(S22-R22)/R22 -> 0.057142857 | V22: 2017 | W22: ='Raw Data'!V148 -> 126.8 | X22: ='Raw Data'!V181 -> 136.6 | Y22: =(X22-W22)/W22 -> 0.077287066 | AA22: 2017 | AB22: ='Raw Data'!X148 -> 127.1 | AC22: ='Raw Data'!X181 -> 133.1 | AD22: =(AC22-AB22)/AB22 -> 0.047206924
A23: =A22+1 -> 2018 | B23: ='Raw Data'!D184+'Raw Data'!E184+'Raw Data'!F184+'Raw Data'!G184+'Raw Data'!H184+'Raw Data'!I184+'Raw Data'!J184+'Raw Data'!K184+'Raw Data'!L184+'Raw Data'!M184+'Raw Data'!N184+'Raw Data'!O184+'Raw Data'!P184 -> 1779.9 | C23: =SUM('Raw Data'!D217:P217) -> 1762.8 | D23: =(C23-B23)/B23 -> -0.0096072813 | F23: =F22+1 -> 2018 | G23: ='Raw Data'!Q184+'Raw Data'!Y184+'Raw Data'!Z184+'Raw Data'!AA184+'Raw Data'!AB184+'Raw Data'!AC184 -> 799.1 | H23: ='Raw Data'!Q217+'Raw Data'!Y217+'Raw Data'!Z217+'Raw Data'!AA217+'Raw Data'!AB217+'Raw Data'!AC217 -> 842.5 | I23: =(H23-G23)/G23 -> 0.0543111 | K23: =K22+1 -> 2018 | L23: =SUM('Raw Data'!R184:T184) -> 421.3 | M23: =SUM('Raw Data'!R217:T217) -> 434.3 | N23: =(M23-L23)/L23 -> 0.030856872 | Q23: =Q22+1 -> 2018 | R23: ='Raw Data'!U184+'Raw Data'!W184 -> 275.3 | S23: ='Raw Data'!U217+'Raw Data'!W217 -> 289.7 | T23: =(S23-R23)/R23 -> 0.052306575 | V23: =V22+1 -> 2018 | W23: ='Raw Data'!V184 -> 136.6 | X23: ='Raw Data'!V217 -> 142.7 | Y23: =(X23-W23)/W23 -> 0.04465593 | AA23: =AA22+1 -> 2018 | AB23: ='Raw Data'!X184 -> 133.3 | AC23: ='Raw Data'!X217 -> 144.9 | AD23: =(AC23-AB23)/AB23 -> 0.087021755
A24: =A23+1 -> 2019 | B24: ='Raw Data'!D220+'Raw Data'!E220+'Raw Data'!F220+'Raw Data'!G220+'Raw Data'!H220+'Raw Data'!I220+'Raw Data'!J220+'Raw Data'!K220+'Raw Data'!L220+'Raw Data'!M220+'Raw Data'!N220+'Raw Data'!O220+'Raw Data'!P220 -> 1753.4 | C24: =SUM('Raw Data'!D250:P250) -> 1946.1 | D24: =(C24-B24)/B24 -> 0.10990076 | F24: =F23+1 -> 2019 | G24: ='Raw Data'!Q220+'Raw Data'!Y220+'Raw Data'!Z220+'Raw Data'!AA220+'Raw Data'!AB220+'Raw Data'!AC220 -> 843.1 | H24: ='Raw Data'!Q250+'Raw Data'!Y250+'Raw Data'!Z250+'Raw Data'!AA250+'Raw Data'!AB250+'Raw Data'!AC250 -> 879.2 | I24: =(H24-G24)/G24 -> 0.042818171 | K24: =K23+1 -> 2019 | L24: =SUM('Raw Data'!R220:T220) -> 433 | M24: =SUM('Raw Data'!R250:T250) -> 440.6 | N24: =(M24-L24)/L24 -> 0.017551963 | Q24: =Q23+1 -> 2019 | R24: ='Raw Data'!U220+'Raw Data'!W220 -> 291.3 | S24: ='Raw Data'!U250+'Raw Data'!W250 -> 298.6 | T24: =(S24-R24)/R24 -> 0.025060076 | V24: =V23+1 -> 2019 | W24: ='Raw Data'!V220 -> 139.5 | X24: ='Raw Data'!V250 -> 143.7 | Y24: =(X24-W24)/W24 -> 0.030107527 | AA24: =AA23+1 -> 2019 | AB24: ='Raw Data'!X220 -> 145.1 | AC24: ='Raw Data'!X250 -> 150.4 | AD24: =(AC24-AB24)/AB24 -> 0.036526533
A25: =A24+1 -> 2020 | B25: ='Raw Data'!D253+'Raw Data'!E253+'Raw Data'!F253+'Raw Data'!G253+'Raw Data'!H253+'Raw Data'!I253+'Raw Data'!J253+'Raw Data'!K253+'Raw Data'!L253+'Raw Data'!M253+'Raw Data'!N253+'Raw Data'!O253+'Raw Data'!P253 -> 1940.4 | C25: =SUM('Raw Data'!D286:P286) -> 2109.1 | D25: =(C25-B25)/B25 -> 0.086940837 | F25: =F24+1 -> 2020 | G25: ='Raw Data'!Q253+'Raw Data'!Y253+'Raw Data'!Z253+'Raw Data'!AA253+'Raw Data'!AB253+'Raw Data'!AC253 -> 884.7 | H25: ='Raw Data'!Q286+'Raw Data'!Y286+'Raw Data'!Z286+'Raw Data'!AA286+'Raw Data'!AB286+'Raw Data'!AC286 -> 942.3 | I25: =(H25-G25)/G25 -> 0.065106816 | K25: =K24+1 -> 2020 | L25: =SUM('Raw Data'!R253:T253) -> 441.2 | M25: =SUM('Raw Data'!R286:T286) -> 454 | N25: =(M25-L25)/L25 -> 0.029011786 | Q25: =Q24+1 -> 2020 | R25: ='Raw Data'!U253+'Raw Data'!W253 -> 300.1 | S25: ='Raw Data'!U286+'Raw Data'!W286 -> 308.1 | T25: =(S25-R25)/R25 -> 0.026657781 | V25: =V24+1 -> 2020 | W25: ='Raw Data'!V253 -> 144.6 | X25: ='Raw Data'!V286 -> 144.6 | Y25: =(X25-W25)/W25 -> 0 | AA25: =AA24+1 -> 2020 | AB25: ='Raw Data'!X253 -> 151.2 | AC25: ='Raw Data'!X286 -> 158.3 | AD25: =(AC25-AB25)/AB25 -> 0.046957672
A26: =A25+1 -> 2021 | B26: ='Raw Data'!D289+'Raw Data'!E289+'Raw Data'!F289+'Raw Data'!G289+'Raw Data'!H289+'Raw Data'!I289+'Raw Data'!J289+'Raw Data'!K289+'Raw Data'!L289+'Raw Data'!M289+'Raw Data'!N289+'Raw Data'!O289+'Raw Data'!P289 -> 2076.5 | C26: =SUM('Raw Data'!D322:P322) -> 2180.9 | D26: =(C26-B26)/B26 -> 0.050276908 | F26: =F25+1 -> 2021 | G26: ='Raw Data'!Q289+'Raw Data'!Y289+'Raw Data'!Z289+'Raw Data'!AA289+'Raw Data'!AB289+'Raw Data'!AC289 -> 945.9 | H26: ='Raw Data'!Q322+'Raw Data'!Y322+'Raw Data'!Z322+'Raw Data'!AA322+'Raw Data'!AB322+'Raw Data'!AC322 -> 997.7 | I26: =(H26-G26)/G26 -> 0.05476266 | K26: =K25+1 -> 2021 | L26: =SUM('Raw Data'!R289:T289) -> 455.8 | M26: =SUM('Raw Data'!R322:T322) -> 494.2 | N26: =(M26-L26)/L26 -> 0.084247477 | Q26: =Q25+1 -> 2021 | R26: ='Raw Data'!U289+'Raw Data'!W289 -> 307.7 | S26: ='Raw Data'!U322+'Raw Data'!W322 -> 323.6 | T26: =(S26-R26)/R26 -> 0.051673708 | V26: =V25+1 -> 2021 | W26: ='Raw Data'!V289 -> 147.9 | X26: ='Raw Data'!V322 -> 164.1 | Y26: =(X26-W26)/W26 -> 0.10953347 | AA26: =AA25+1 -> 2021 | AB26: ='Raw Data'!X289 -> 159.3 | AC26: ='Raw Data'!X322 -> 170.6 | AD26: =(AC26-AB26)/AB26 -> 0.070935342
A27: =A26+1 -> 2022 | B27: ='Raw Data'!D325+'Raw Data'!E325+'Raw Data'!F325+'Raw Data'!G325++'Raw Data'!H325+'Raw Data'!I325+'Raw Data'!J325+'Raw Data'!K325+'Raw Data'!L325+'Raw Data'!M325+'Raw Data'!N325+'Raw Data'!O325+'Raw Data'!P325 -> 2164.2 | C27: =SUM('Raw Data'!D358:P358) -> 2283.4 | D27: =(C27-B27)/B27 -> 0.055078089 | F27: =F26+1 -> 2022 | G27: ='Raw Data'!Q325+'Raw Data'!Y325+'Raw Data'!Z325+'Raw Data'!AA325+'Raw Data'!AB325+'Raw Data'!AC325 -> 1000.3 | H27: ='Raw Data'!Q358+'Raw Data'!Y358+'Raw Data'!Z358+'Raw Data'!AA358+'Raw Data'!AB358+'Raw Data'!AC358 -> 1051.5 | I27: =(H27-G27)/G27 -> 0.051184645 | K27: =K26+1 -> 2022 | L27: =SUM('Raw Data'!R325:T325) -> 499.1 | M27: =SUM('Raw Data'!R358:T358) -> 544 | N27: =(M27-L27)/L27 -> 0.089961931 | Q27: =Q26+1 -> 2022 | R27: ='Raw Data'!U325+'Raw Data'!W325 -> 325.6 | S27: ='Raw Data'!U358+'Raw Data'!W358 -> 342.8 | T27: =(S27-R27)/R27 -> 0.052825553 | V27: =V26+1 -> 2022 | W27: ='Raw Data'!V325 -> 164.2 | X27: ='Raw Data'!V358 -> 182 | Y27: =(X27-W27)/W27 -> 0.10840438 | AA27: =AA26+1 -> 2022 | AB27: ='Raw Data'!X325 -> 171.4 | AC27: ='Raw Data'!X358 -> 181.1 | AD27: =(AC27-AB27)/AB27 -> 0.056592765
A28: =A27+1 -> 2023 | B28: ='Raw Data'!D361+'Raw Data'!E361+'Raw Data'!F361+'Raw Data'!G361+'Raw Data'!H361+'Raw Data'!I361+'Raw Data'!J361+'Raw Data'!K361+'Raw Data'!L361+'Raw Data'!M361+'Raw Data'!N361+'Raw Data'!O361+'Raw Data'!P361 -> 2292.7 | D28: We only have data till may 2023 | F28: =F27+1 -> 2023 | G28: ='Raw Data'!Q361+'Raw Data'!Y361+'Raw Data'!Z361+'Raw Data'!AA361+'Raw Data'!AB361+'Raw Data'!AC361 -> 1057 | I28: We only have data till may 2023 | K28: =K27+1 -> 2023 | L28: =SUM('Raw Data'!R361:T361) -> 546.3 | N28: We only have data till may 2023 | Q28: =Q27+1 -> 2023 | R28: ='Raw Data'!U361+'Raw Data'!W361 -> 345 | T28: We only have data till may 2023 | V28: =V27+1 -> 2023 | W28: ='Raw Data'!V361 -> 182 | Y28: We only have data till may 2023 | AA28: =AA27+1 -> 2023 | AB28: ='Raw Data'!X361 -> 182.3 | AD28: We only have data till may 2023
A31: Urban
A32: Category Wise
A33: Food | F33: Miscellaneous | K33: Clothing | Q33: Housing | V33: Energy | AA33: Health
A34: Years | B34: Jan | C34: Dec | D34: YoY%Change | F34: Years | G34: Jan | H34: Dec | I34: YoY%Change | K34: Years | L34: Jan | M34: Dec | N34: YoY%Change | Q34: Years | R34: Jan | S34: Dec | T34: YoY%Change | V34: Years | W34: Jan | X34: Dec | Y34: YoY%Change | AA34: Years | AB34: Jan | AC34: Dec | AD34: YoY%Change
A35: 2017 | B35: =SUM('Raw Data'!D147:P147) -> 1713.2 | C35: =SUM('Raw Data'!D180:P180) -> 1767.5 | D35: =(C35-B35)/B35 -> 0.031695074 | F35: 2017 | G35: ='Raw Data'!Q147+'Raw Data'!Y147+'Raw Data'!Z147+'Raw Data'!AA147+'Raw Data'!AB147+'Raw Data'!AC147 -> 758.2 | H35: ='Raw Data'!Q180+'Raw Data'!Y180+'Raw Data'!Z180+'Raw Data'!AA180+'Raw Data'!AB180+'Raw Data'!AC180 -> 784.3 | I35: =(H35-G35)/G35 -> 0.034423635 | K35: 2017 | L35: =SUM('Raw Data'!R147:T147) -> 381.5 | M35: =SUM('Raw Data'!R180:T180) -> 395.2 | N35: =(M35-L35)/L35 -> 0.035910878 | Q35: 2017 | R35: ='Raw Data'!U147+'Raw Data'!W147 -> 254.7 | S35: ='Raw Data'!U180+'Raw Data'!W180 -> 268.4 | T35: =(S35-R35)/R35 -> 0.053788771 | V35: 2017 | W35: ='Raw Data'!V147 -> 118 | X35: ='Raw Data'!V180 -> 126.8 | Y35: =(X35-W35)/W35 -> 0.074576271 | AA35: 2017 | AB35: ='Raw Data'!X147 -> 122.6 | AC35: ='Raw Data'!X180 -> 128.2 | AD35: =(AC35-AB35)/AB35 -> 0.045676998
A36: =A35+1 -> 2018 | B36: =SUM('Raw Data'!D183:P183) -> 1748.3 | C36: =SUM('Raw Data'!D216:P216) -> 1746.6 | D36: =(C36-B36)/B36 -> -0.00097237316 | F36: =F35+1 -> 2018 | G36: ='Raw Data'!Q183+'Raw Data'!Y183+'Raw Data'!Z183+'Raw Data'!AA183+'Raw Data'!AB183+'Raw Data'!AC183 -> 788.6 | H36: ='Raw Data'!Q216+'Raw Data'!Y216+'Raw Data'!Z216+'Raw Data'!AA216+'Raw Data'!AB216+'Raw Data'!AC216 -> 824.1 | I36: =(H36-G36)/G36 -> 0.045016485 | K36: =K35+1 -> 2018 | L36: =SUM('Raw Data'!R183:T183) -> 396.3 | M36: =SUM('Raw Data'!R216:T216) -> 413.8 | N36: =(M36-L36)/L36 -> 0.044158466 | Q36: =Q35+1 -> 2018 | R36: ='Raw Data'!U183+'Raw Data'!W183 -> 269.9 | S36: ='Raw Data'!U216+'Raw Data'!W216 -> 282.7 | T36: =(S36-R36)/R36 -> 0.047424972 | V36: =V35+1 -> 2018 | W36: ='Raw Data'!V183 -> 127.3 | X36: ='Raw Data'!V216 -> 132.4 | Y36: =(X36-W36)/W36 -> 0.040062844 | AA36: =AA35+1 -> 2018 | AB36: ='Raw Data'!X183 -> 129 | AC36: ='Raw Data'!X216 -> 137.3 | AD36: =(AC36-AB36)/AB36 -> 0.064341085
A37: =A36+1 -> 2019 | B37: =SUM('Raw Data'!D219:P219) -> 1744.3 | C37: =SUM('Raw Data'!D249:P249) -> 1956.7 | D37: =(C37-B37)/B37 -> 0.12176804 | F37: =F36+1 -> 2019 | G37: ='Raw Data'!Q219+'Raw Data'!Y219+'Raw Data'!Z219+'Raw Data'!AA219+'Raw Data'!AB219+'Raw Data'!AC219 -> 825.3 | H37: ='Raw Data'!Q249+'Raw Data'!Y249+'Raw Data'!Z249+'Raw Data'!AA249+'Raw Data'!AB249+'Raw Data'!AC249 -> 862.2 | I37: =(H37-G37)/G37 -> 0.044711014 | K37: =K36+1 -> 2019 | L37: =SUM('Raw Data'!R219:T219) -> 414.5 | M37: =SUM('Raw Data'!R249:T249) -> 424.2 | N37: =(M37-L37)/L37 -> 0.023401689 | Q37: =Q36+1 -> 2019 | R37: ='Raw Data'!U219+'Raw Data'!W219 -> 284 | S37: ='Raw Data'!U249+'Raw Data'!W249 -> 292.6 | T37: =(S37-R37)/R37 -> 0.03028169 | V37: =V36+1 -> 2019 | W37: ='Raw Data'!V219 -> 128.6 | X37: ='Raw Data'!V249 -> 133.6 | Y37: =(X37-W37)/W37 -> 0.038880249 | AA37: =AA36+1 -> 2019 | AB37: ='Raw Data'!X219 -> 137.8 | AC37: ='Raw Data'!X249 -> 143.2 | AD37: =(AC37-AB37)/AB37 -> 0.039187228
A38: =A37+1 -> 2020 | B38: =SUM('Raw Data'!D252:P252) -> 1945.4 | C38: =SUM('Raw Data'!D285:P285) -> 2125.4 | D38: =(C38-B38)/B38 -> 0.092525959 | F38: =F37+1 -> 2020 | G38: ='Raw Data'!Q252+'Raw Data'!Y252+'Raw Data'!Z252+'Raw Data'!AA252+'Raw Data'!AB252+'Raw Data'!AC252 -> 866.7 | H38: ='Raw Data'!Q285+'Raw Data'!Y285+'Raw Data'!Z285+'Raw Data'!AA285+'Raw Data'!AB285+'Raw Data'!AC285 -> 931.7 | I38: =(H38-G38)/G38 -> 0.074997115 | K38: =K37+1 -> 2020 | L38: =SUM('Raw Data'!R252:T252) -> 425.1 | M38: =SUM('Raw Data'!R285:T285) -> 438.2 | N38: =(M38-L38)/L38 -> 0.030816279 | Q38: =Q37+1 -> 2020 | R38: ='Raw Data'!U252+'Raw Data'!W252 -> 294 | S38: ='Raw Data'!U285+'Raw Data'!W285 -> 303.9 | T38: =(S38-R38)/R38 -> 0.033673469 | V38: =V37+1 -> 2020 | W38: ='Raw Data'!V252 -> 135.1 | X38: ='Raw Data'!V285 -> 137.9 | Y38: =(X38-W38)/W38 -> 0.020725389 | AA38: =AA37+1 -> 2020 | AB38: ='Raw Data'!X252 -> 143.8 | AC38: ='Raw Data'!X285 -> 152.9 | AD38: =(AC38-AB38)/AB38 -> 0.063282337
A39: =A38+1 -> 2021 | B39: =SUM('Raw Data'!D288:P288) -> 2097 | C39: =SUM('Raw Data'!D321:P321) -> 2206.3 | D39: =(C39-B39)/B39 -> 0.052122079 | F39: =F38+1 -> 2021 | G39: ='Raw Data'!Q288++'Raw Data'!Y288+'Raw Data'!Z288+'Raw Data'!AA288+'Raw Data'!AB288+'Raw Data'!AC288 -> 935.5 | H39: ='Raw Data'!Q321+'Raw Data'!Y321+'Raw Data'!Z321+'Raw Data'!AA321+'Raw Data'!AB321+'Raw Data'!AC321 -> 987 | I39: =(H39-G39)/G39 -> 0.055050775 | K39: =K38+1 -> 2021 | L39: =SUM('Raw Data'!R288:T288) -> 440 | M39: =SUM('Raw Data'!R321:T321) -> 470.7 | N39: =(M39-L39)/L39 -> 0.069772727 | Q39: =Q38+1 -> 2021 | R39: ='Raw Data'!U288+'Raw Data'!W288 -> 303.4 | S39: ='Raw Data'!U321+'Raw Data'!W321 -> 319.4 | T39: =(S39-R39)/R39 -> 0.052735662 | V39: =V38+1 -> 2021 | W39: ='Raw Data'!V288 -> 142.9 | X39: ='Raw Data'!V321 -> 161.7 | Y39: =(X39-W39)/W39 -> 0.13156053 | AA39: =AA38+1 -> 2021 | AB39: ='Raw Data'!X288 -> 154.1 | AC39: ='Raw Data'!X321 -> 165.1 | AD39: =(AC39-AB39)/AB39 -> 0.071382219
A40: =A39+1 -> 2022 | B40: =SUM('Raw Data'!D324:P324) -> 2186.7 | C40: =SUM('Raw Data'!D357:P357) -> 2295.8 | D40: =(C40-B40)/B40 -> 0.049892532 | F40: =F39+1 -> 2022 | G40: ='Raw Data'!Q324+'Raw Data'!Y324+'Raw Data'!Z324+'Raw Data'!AA324+'Raw Data'!AB324+'Raw Data'!AC324 -> 989.9 | H40: ='Raw Data'!Q357+'Raw Data'!Y357+'Raw Data'!Z357+'Raw Data'!AA357+'Raw Data'!AB357+'Raw Data'!AC357 -> 1043.6 | I40: =(H40-G40)/G40 -> 0.054247904 | K40: =K39+1 -> 2022 | L40: =SUM('Raw Data'!R324:T324) -> 475.4 | M40: =SUM('Raw Data'!R357:T357) -> 517.9 | N40: =(M40-L40)/L40 -> 0.089398401 | Q40: =Q39+1 -> 2022 | R40: ='Raw Data'!U324+'Raw Data'!W324 -> 321.3 | S40: ='Raw Data'!U357+'Raw Data'!W357 -> 338 | T40: =(S40-R40)/R40 -> 0.051976346 | V40: =V39+1 -> 2022 | W40: ='Raw Data'!V324 -> 161.6 | X40: ='Raw Data'!V357 -> 180.6 | Y40: =(X40-W40)/W40 -> 0.11757426 | AA40: =AA39+1 -> 2022 | AB40: ='Raw Data'!X324 -> 166.1 | AC40: ='Raw Data'!X357 -> 177.2 | AD40: =(AC40-AB40)/AB40 -> 0.066827213
A41: =A40+1 -> 2023 | B41: =SUM('Raw Data'!D360:P360) -> 2310.2 | D41: We only have data till may 2023 | F41: =F40+1 -> 2023 | G41: ='Raw Data'!Q360+'Raw Data'!Y360+'Raw Data'!Z360+'Raw Data'!AA360+'Raw Data'!AB360+'Raw Data'!AC360 -> 1048.4 | I41: We only have data till may 2023 | K41: =K40+1 -> 2023 | L41: =SUM('Raw Data'!R360:T360) -> 520.6 | N41: We only have data till may 2023 | Q41: =Q40+1 -> 2023 | R41: ='Raw Data'!U360+'Raw Data'!W360 -> 340.1 | T41: We only have data till may 2023 | V41: =V40+1 -> 2023 | W41: ='Raw Data'!V360 -> 180.1 | Y41: We only have data till may 2023 | AA41: =AA40+1 -> 2023 | AB41: ='Raw Data'!X360 -> 178.5 | AD41: We only have data till may 2023
A45: Rural
A46: Category Wise
A47: Food | F47: Miscellaneous | K47: Clothing | Q47: Housing | V47: Energy | AA47: Health
A48: Years | B48: Jan | C48: Dec | D48: YoY%Change | F48: Years | G48: Jan | H48: Dec | I48: YoY%Change | K48: Years | L48: Jan | M48: Dec | N48: YoY%Change | Q48: Years | R48: Jan | S48: Dec | T48: YoY%Change | V48: Years | W48: Jan | X48: Dec | Y48: YoY%Change | AA48: Years | AB48: Jan | AC48: Dec | AD48: YoY%Change
A49: 2017 | B49: =SUM('Raw Data'!D146:P146) -> 1737.3 | C49: =SUM('Raw Data'!D179:P179) -> 1813.6 | D49: =(C49-B49)/B49 -> 0.043918724 | F49: 2017 | G49: ='Raw Data'!Q146+'Raw Data'!Y146+'Raw Data'!Z146+'Raw Data'!AA146+'Raw Data'!AB146+'Raw Data'!AC146 -> 772.7 | H49: ='Raw Data'!Q179+'Raw Data'!Y179+'Raw Data'!Z179+'Raw Data'!AA179+'Raw Data'!AB179+'Raw Data'!AC179 -> 809.4 | I49: =(H49-G49)/G49 -> 0.047495794 | K49: 2017 | L49: =SUM('Raw Data'!R146:T146) -> 416.5 | M49: =SUM('Raw Data'!R179:T179) -> 437.1 | N49: =(M49-L49)/L49 -> 0.049459784 | Q49: 2017 | R49: ='Raw Data'!U147+'Raw Data'!W147 -> 254.7 | S49: ='Raw Data'!U180+'Raw Data'!W180 -> 268.4 | T49: =(S49-R49)/R49 -> 0.053788771 | V49: 2017 | W49: ='Raw Data'!V146 -> 132.1 | X49: ='Raw Data'!V179 -> 142.6 | Y49: =(X49-W49)/W49 -> 0.079485238 | AA49: 2017 | AB49: ='Raw Data'!X146 -> 129.9 | AC49: ='Raw Data'!X179 -> 136.1 | AD49: =(AC49-AB49)/AB49 -> 0.047729022
...

Sheet PS3
A1: 3. With India's retail inflation reaching a 3-month high of 5.55% in November 2023, largely due to a sharp rise in food prices. Analyze the following for 12 months ending May’23
A2: Investigate trends in the prices of broader food bucket category and evaluate month-on-month changes. Highlight month with highest and lowest food inflation
A3: The time frame is between June 22 to May 23.
A4: Rural
A5: Category wise (Food)
A6: Year | B6: Month | C6: CPI(Food) | D6: MoM% | E6: Cereals and products | F6: Meat and fish | G6: Egg | H6: Milk and products | I6: Oils and fats | J6: Fruits | K6: Vegetables | L6: Pulses and products | M6: Sugar and Confectionery | N6: Spices | O6: Non-alcoholic beverages | P6: Prepared meals, snacks, sweets etc. | Q6: Food and beverages
A7: 2022 | B7: May | C7: =SUM('Raw Data'!D335:P335) -> 2226.8 | E7: 152.9 | F7: 214.7 | G7: 161.4 | H7: 164.6 | I7: 209.9 | J7: 168 | K7: 160.4 | L7: 165 | M7: 118.9 | N7: 186.6 | O7: 173.2 | P7: 180.4 | Q7: 170.8
A8: 2022 | B8: June | C8: =SUM('Raw Data'!D338:P338) -> 2248.3 | D8: =(C8-C7)/C7 -> 0.0096551105 | E8: 153.8 | F8: 217.2 | G8: 169.6 | H8: 165.4 | I8: 208.1 | J8: 165.8 | K8: 167.3 | L8: 164.6 | M8: 119.1 | N8: 188.9 | O8: 174.2 | P8: 181.9 | Q8: 172.4
A9: 2022 | B9: July | C9: =SUM('Raw Data'!D341:P341) -> 2252.5 | D9: =(C9-C8)/C8 -> 0.0018680781 | E9: 155.2 | F9: 210.8 | G9: 174.3 | H9: 166.3 | I9: 202.2 | J9: 169.6 | K9: 168.6 | L9: 164.4 | M9: 119.2 | N9: 191.8 | O9: 174.5 | P9: 183.1 | Q9: 172.5
A10: 2022 | B10: August | C10: =SUM('Raw Data'!D344:P344) -> 2255.8 | D10: =(C10-C9)/C9 -> 0.0014650388 | E10: 159.5 | F10: 204.1 | G10: 168.3 | H10: 167.9 | I10: 198.1 | J10: 169.2 | K10: 173.1 | L10: 167.1 | M10: 120.2 | N10: 195.6 | O10: 174.8 | P10: 184 | Q10: 173.9
A11: 2022 | B11: September | C11: =SUM('Raw Data'!D347:P347) -> 2267.8 | D11: =(C11-C10)/C10 -> 0.0053196205 | E11: 162.9 | F11: 206.7 | G11: 169 | H11: 169.5 | I11: 194.1 | J11: 164.1 | K11: 176.9 | L11: 169 | M11: 120.8 | N11: 199.1 | O11: 175.4 | P11: 184.8 | Q11: 175.5
A12: 2022 | B12: October | C12: =SUM('Raw Data'!D350:P350) -> 2284.5 | D12: =(C12-C11)/C11 -> 0.0073639651 | E12: 164.7 | F12: 208.8 | G12: 170.3 | H12: 170.9 | I12: 191.6 | J12: 162.2 | K12: 184.8 | L12: 169.7 | M12: 121.1 | N12: 201.6 | O12: 175.8 | P12: 185.6 | Q12: 177.4
A13: 2022 | B13: November | C13: =SUM('Raw Data'!D353:P353) -> 2287.7 | D13: =(C13-C12)/C12 -> 0.0014007441 | E13: 166.9 | F13: 207.2 | G13: 180.2 | H13: 172.3 | I13: 194 | J13: 159.1 | K13: 171.6 | L13: 170.2 | M13: 121.5 | N13: 204.8 | O13: 176.4 | P13: 186.9 | Q13: 176.6
A14: 2022 | B14: December | C14: =SUM('Raw Data'!D356:P356) -> 2277.1 | D14: =(C14-C13)/C13 -> -0.0046334747 | E14: 168.8 | F14: 206.9 | G14: 189.1 | H14: 173.4 | I14: 193.9 | J14: 156.7 | K14: 150.2 | L14: 170.5 | M14: 121.2 | N14: 207.5 | O14: 176.8 | P14: 187.7 | Q14: 174.4
A15: 2023 | B15: January | C15: =SUM('Raw Data'!D359:P359) -> 2283.2 | D15: =(C15-C14)/C14 -> 0.0026788459 | E15: 174 | F15: 208.3 | G15: 192.9 | H15: 174.3 | I15: 192.6 | J15: 156.3 | K15: 142.9 | L15: 170.7 | M15: 120.3 | N15: 210.5 | O15: 176.9 | P15: 188.5 | Q15: 175
A16: 2023 | B16: February | C16: =SUM('Raw Data'!D362:P362) -> 2265.7 | D16: =(C16-C15)/C15 -> -0.0076646811 | E16: 174.2 | F16: 205.2 | G16: 173.9 | H16: 177 | I16: 183.4 | J16: 167.2 | K16: 140.9 | L16: 170.4 | M16: 119.1 | N16: 212.1 | O16: 177.6 | P16: 189.9 | Q16: 174.8
A17: 2023 | B17: March | C17: =SUM('Raw Data'!D365:P365) -> 2265.8 | D17: =(C17-C16)/C16 -> 4.413647e-05 | E17: 174.3 | F17: 205.2 | G17: 173.9 | H17: 177 | I17: 183.3 | J17: 167.2 | K17: 140.9 | L17: 170.5 | M17: 119.1 | N17: 212.1 | O17: 177.6 | P17: 189.9 | Q17: 174.8
A18: 2023 | B18: April | C18: =SUM('Raw Data'!D368:P368) -> 2274.2 | D18: =(C18-C17)/C17 -> 0.0037072998 | E18: 173.3 | F18: 206.9 | G18: 167.9 | H18: 178.2 | I18: 178.5 | J18: 173.7 | K18: 142.8 | L18: 172.8 | M18: 120.4 | N18: 215.5 | O18: 178.2 | P18: 190.5 | Q18: 175.5
A19: 2023 | B19: May | C19: =SUM('Raw Data'!D371:P371) -> 2290.7 | D19: =(C19-C18)/C18 -> 0.0072552986 | E19: 173.2 | F19: 211.5 | G19: 171 | H19: 179.6 | I19: 173.3 | J19: 169 | K19: 148.7 | L19: 174.9 | M19: 121.9 | N19: 221 | O19: 178.7 | P19: 191.1 | Q19: 176.8
A22: Urban
A23: Category wise (Food)
A24: Year | B24: Month | C24: CPI(Food) | D24: MoM% | E24: Cereals and products | F24: Meat and fish | G24: Egg | H24: Milk and products | I24: Oils and fats | J24: Fruits | K24: Vegetables | L24: Pulses and products | M24: Sugar and Confectionery | N24: Spices | O24: Non-alcoholic beverages | P24: Prepared meals, snacks, sweets etc. | Q24: Food and beverages
A25: 2022 | B25: May | C25: =SUM(E25:Q25) -> 2262.2 | E25: 156.7 | F25: 221.2 | G25: 164.1 | H25: 165.4 | I25: 189.5 | J25: 174.5 | K25: 203.2 | L25: 164.1 | M25: 121.2 | N25: 181.4 | O25: 158.5 | P25: 184.9 | Q25: 177.5
A26: 2022 | B26: June | C26: =SUM(E26:Q26) -> 2287.5 | D26: =(C26-C25)/C25 -> 0.011183803 | E26: 157.5 | F26: 223.4 | G26: 172.8 | H26: 166.4 | I26: 188.6 | J26: 174.1 | K26: 211.5 | L26: 163.6 | M26: 121.4 | N26: 183.5 | O26: 159.1 | P26: 186.3 | Q26: 179.3
A27: 2022 | B27: July | C27: =SUM(E27:Q27) -> 2291.6 | D27: =(C27-C26)/C26 -> 0.0017923497 | E27: 159.3 | F27: 217.1 | G27: 176.6 | H27: 167.1 | I27: 184.8 | J27: 179.5 | K27: 208.5 | L27: 164 | M27: 121.5 | N27: 186.3 | O27: 159.8 | P27: 187.7 | Q27: 179.4
A28: 2022 | B28: August | C28: =SUM(E28:Q28) -> 2293.7 | D28: =(C28-C27)/C27 -> 0.00091639029 | E28: 162.1 | F28: 210.9 | G28: 170.6 | H28: 168.4 | I28: 182.5 | J28: 177.1 | K28: 213.1 | L28: 167.3 | M28: 122.2 | N28: 189.7 | O28: 160.5 | P28: 188.9 | Q28: 180.4
A29: 2022 | B29: September | C29: =SUM(E29:Q29) -> 2306.4 | D29: =(C29-C28)/C28 -> 0.0055369054 | E29: 164.9 | F29: 213.7 | G29: 170.9 | H29: 170.1 | I29: 179.3 | J29: 167.5 | K29: 220.8 | L29: 169.2 | M29: 123.1 | N29: 193.6 | O29: 161.1 | P29: 190.4 | Q29: 181.8
A30: 2022 | B30: October | C30: =SUM(E30:Q30) -> 2322.3 | D30: =(C30-C29)/C29 -> 0.0068938606 | E30: 166.4 | F30: 214.9 | G30: 171.9 | H30: 171 | I30: 177.7 | J30: 165.7 | K30: 228.6 | L30: 169.9 | M30: 123.4 | N30: 196.4 | O30: 161.6 | P30: 191.5 | Q30: 183.3
A31: 2022 | B31: November | C31: =SUM(E31:Q31) -> 2314.4 | D31: =(C31-C30)/C30 -> -0.0034017999 | E31: 168.4 | F31: 213.4 | G31: 183.2 | H31: 172.3 | I31: 180 | J31: 162.6 | K31: 205.5 | L31: 171 | M31: 123.4 | N31: 198.8 | O31: 162.1 | P31: 192.4 | Q31: 181.3
A32: 2022 | B32: December | C32: =SUM(E32:Q32) -> 2295.8 | D32: =(C32-C31)/C31 -> -0.0080366402 | E32: 170.2 | F32: 212.9 | G32: 191.9 | H32: 173.9 | I32: 179.1 | J32: 159.5 | K32: 178.7 | L32: 171.3 | M32: 123.1 | N32: 200.5 | O32: 162.8 | P32: 193.3 | Q32: 178.6
A33: 2023 | B33: January | C33: =SUM(E33:Q33) -> 2310.2 | D33: =(C33-C32)/C32 -> 0.0062723234 | E33: 173.3 | F33: 215.2 | G33: 197 | H33: 175.2 | I33: 178 | J33: 160.5 | K33: 175.3 | L33: 171.2 | M33: 122.7 | N33: 204.3 | O33: 163.7 | P33: 194.3 | Q33: 179.5
A34: 2023 | B34: February | C34: =SUM(E34:Q34) -> 2303.2 | D34: =(C34-C33)/C33 -> -0.0030300407 | E34: 174.7 | F34: 212.2 | G34: 177.2 | H34: 177.9 | I34: 172.2 | J34: 172.1 | K34: 175.8 | L34: 172.2 | M34: 121.9 | N34: 204.8 | O34: 164.9 | P34: 196.6 | Q34: 180.7
A35: 2023 | B35: March | C35: =SUM(E35:Q35) -> 2303.4 | D35: =(C35-C34)/C34 -> 8.6835707e-05 | E35: 174.7 | F35: 212.2 | G35: 177.2 | H35: 177.9 | I35: 172.2 | J35: 172.1 | K35: 175.9 | L35: 172.2 | M35: 121.9 | N35: 204.8 | O35: 164.9 | P35: 196.6 | Q35: 180.8
A36: 2023 | B36: April | C36: =SUM(E36:Q36) -> 2317.7 | D36: =(C36-C35)/C35 -> 0.0062082139 | E36: 174.8 | F36: 213.7 | G36: 172.4 | H36: 178.8 | I36: 168.7 | J36: 179.2 | K36: 179.9 | L36: 174.7 | M36: 123.1 | N36: 207.8 | O36: 165.5 | P36: 197 | Q36: 182.1
